Workbook

Sheet ENCABEZADO
B3: LOGOTIPO DE LA INSTITUCIÓN (Insertar › Imágenes y colocarlo aquí) | D3: PROYECTO INTEGRADOR · ETAPA 2
D4: Tablero de control de mi plan de carrera
D5: Seguimiento de metas, objetivos, indicadores de desempeño y KPI
B8: Estudiante | C8: Valeria Ochoa | E8: Carrera | F8: (escribe aquí tu carrera)
B9: ID | C9: 5277522 | E9: Materia | F9: (escribe aquí el nombre de la materia)
B10: Institución | C10: Universidad Autónoma de Guadalajara | E10: Docente | F10: (escribe aquí el nombre del docente)
B11: Actividad | C11: Proyecto integrador · Etapa 2 | E11: Fecha de entrega | F11: 46320
B13: MI PLAN DE CARRERA: META, OBJETIVOS, ACTIVIDADES, INDICADORES Y KPI
B14: Es la tabla de la Etapa 1 con dos columnas nuevas (en verde azulado): un indicador de desempeño y un KPI por cada objetivo específico.
B15: META | C15: OBJETIVO GENERAL | D15: OBJETIVOS ESPECÍFICOS | E15: ACTIVIDADES | F15: INDICADOR DE DESEMPEÑO Nuevo · Etapa 2 | G15: KPI (INDICADOR CLAVE) Nuevo · Etapa 2
B16: Concluir mi carrera y prepararme para oportunidades laborales. | C16: Mejorar mi rendimiento y mis competencias en 12 meses mediante planificación y hábitos sostenibles. | D16: OBJETIVO 1 Organizar y cumplir un horario semanal de estudio en 3 meses. Plazo: semanal, durante 3 meses | E16: 1.1 Crear un calendario semanal con clases, entregas y tiempo de estudio. | F16: Constancia en el estudio Días a la semana en los que hago al menos un bloque de estudio de 45–60 min. Meta: 5 días por semana Se registra: cada semana, en la revisión del domingo | G16: % de cumplimiento del horario Fórmula: Bloques realizados ÷ bloques planificados × 100 Meta: ≥ 80 % Semáforo: ● ≥ 80 % ● 60–79 % ● < 60 %
E17: 1.2 Estudiar al menos 5 días por semana en bloques de 45–60 minutos.
E18: 1.3 Revisar cada domingo las tareas completadas y ajustar el horario.
D19: OBJETIVO 2 Mejorar mi desempeño académico en las asignaturas del semestre. Plazo: semestral | E19: 2.1 Identificar al inicio del mes las asignaturas y temas que me resultan más difíciles. | F19: Evolución de mis calificaciones Promedio por asignatura en cada evaluación (parcial 1, parcial 2 y final) y su variación entre parciales. Meta: promedio general ≥ 8.5 y variación positiva Se registra: después de cada evaluación | G19: % de tareas entregadas a tiempo Fórmula: Tareas entregadas en fecha ÷ tareas asignadas × 100 Meta: ≥ 90 % Semáforo: ● ≥ 90 % ● 75–89 % ● < 75 %
E20: 2.2 Realizar ejercicios o preguntas de repaso al menos dos veces por semana por asignatura prioritaria.
E21: 2.3 Consultar al docente o a un compañero cuando una duda continúe después de estudiar.
D22: OBJETIVO 3 Desarrollar competencias útiles para mi futuro profesional durante los próximos 12 meses. Plazo: 6 a 12 meses | E22: 3.1 Completar al menos un curso, taller o capacitación relacionada con mi carrera. | F22: Acciones de desarrollo profesional Cursos completados, currículum actualizado (sí / no) y charlas o eventos a los que asistí. Meta: 1 curso, CV actualizado y 2 eventos Se registra: cada mes | G22: % de avance del plan profesional Fórmula: Promedio del avance de los 6 hitos del plan, comparado con el avance esperado a la fecha Meta: 100 % a los 12 meses Semáforo: ● al día o adelantado ● ≥ 70 % de lo esperado ● < 70 % de lo esperado
E23: 3.2 Actualizar mi currículum con los estudios, proyectos y habilidades adquiridas.
E24: 3.3 Participar en al menos dos charlas, eventos académicos o actividades de contacto profesional.
B26: ¿Qué diferencia hay entre las dos columnas nuevas? El indicador de desempeño mide cómo voy con las actividades del día a día (por ejemplo, cuántos días estudié en la semana). El KPI es el resultado clave de cada objetivo: tiene una fórmula, una meta y un semáforo que me avisa a tiempo si voy bien, en riesgo o con bajo rendimiento (Parmenter, 2015). Los valores actuales de cada indicador se ven en la hoja TABLERO DE CONTROL.

Sheet TABLERO DE CONTROL
B2: TABLERO DE CONTROL · MI RENDIMIENTO ACADÉMICO
B3: Valeria Ochoa · ID 5277522 · Proyecto integrador, Etapa 2 · Plan de carrera | K3: Corte al: | M3: =REGISTRO!C5 -> 46320 | O3: =COUNT(REGISTRO!E20:E31)&" de 12 semanas registradas" -> 8 de 12 semanas registradas
B5: INDICADORES CLAVE (KPI) · un vistazo al estado de cada objetivo
B6: OBJ. 1 · CUMPLIMIENTO DEL HORARIO | F6: OBJ. 2 · TAREAS ENTREGADAS A TIEMPO | J6: OBJ. 2 · PROMEDIO GENERAL | N6: OBJ. 3 · AVANCE DEL PLAN PROFESIONAL
B7: ='CÁLCULOS'!C5 -> 0.8125 | E7: ● | F7: ='CÁLCULOS'!C7 -> 0.85 | I7: ● | J7: ='CÁLCULOS'!C8 -> 8.43 | M7: ● | N7: ='CÁLCULOS'!C9 -> 0.3 | Q7: ●
B9: ='CÁLCULOS'!D5 -> 0.8 | F9: ='CÁLCULOS'!D7 -> 0.9 | J9: ='CÁLCULOS'!D8 -> 8.5 | N9: ='CÁLCULOS'!D9 -> 0.15
B10: =REPT("█",ROUND('CÁLCULOS'!H5*22,0))&REPT("░",22-ROUND('CÁLCULOS'!H5*22,0)) -> ██████████████████████ | F10: =REPT("█",ROUND('CÁLCULOS'!H7*22,0))&REPT("░",22-ROUND('CÁLCULOS'!H7*22,0)) -> █████████████████████░ | J10: =REPT("█",ROUND('CÁLCULOS'!H8*22,0))&REPT("░",22-ROUND('CÁLCULOS'!H8*22,0)) -> ██████████████████████ | N10: =REPT("█",ROUND('CÁLCULOS'!H9*22,0))&REPT("░",22-ROUND('CÁLCULOS'!H9*22,0)) -> ███████░░░░░░░░░░░░░░░
B11: =UPPER('CÁLCULOS'!G5) -> EN META | F11: =UPPER('CÁLCULOS'!G7) -> EN RIESGO | J11: =UPPER('CÁLCULOS'!G8) -> EN RIESGO | N11: =UPPER('CÁLCULOS'!G9) -> EN META
B13: OBJ. 1 · CUMPLIMIENTO SEMANAL DEL HORARIO (color según semáforo) | L13: OBJ. 2 · ESTADO DE MIS ENTREGAS
B31: OBJ. 2 · EVOLUCIÓN DE CALIFICACIONES POR PARCIAL | L31: OBJ. 3 · HITOS DEL PLAN PROFESIONAL
L45: Cursos completados | N45: Currículum actualizado | P45: Eventos asistidos
L47: ='CÁLCULOS'!B48 -> 0 de 1 | N47: ='CÁLCULOS'!B49 -> En proceso | P47: ='CÁLCULOS'!B50 -> 0 de 2
B49: SEMÁFORO DE OBJETIVOS Y BARRAS DE PROGRESO
B50: Indicador | E50: Objetivo | F50: Valor actual | G50: Meta | H50: Rojo | I50: Amarillo | J50: Verde | K50: Progreso hacia la meta | P50: Estado
B51: ='CÁLCULOS'!A5 -> Cumplimiento del horario | E51: ='CÁLCULOS'!B5 -> Obj. 1 | F51: ='CÁLCULOS'!C5 -> 0.8125 | G51: ='CÁLCULOS'!D5 -> 0.8 | H51: ● | I51: ● | J51: ● | K51: ='CÁLCULOS'!H5 -> 1 | P51: =UPPER('CÁLCULOS'!G5) -> EN META
B52: ='CÁLCULOS'!A6 -> Días de estudio por semana | E52: ='CÁLCULOS'!B6 -> Obj. 1 | F52: ='CÁLCULOS'!C6 -> 4.5 | G52: ='CÁLCULOS'!D6 -> 5 | H52: ● | I52: ● | J52: ● | K52: ='CÁLCULOS'!H6 -> 0.9 | P52: =UPPER('CÁLCULOS'!G6) -> EN RIESGO
B53: ='CÁLCULOS'!A7 -> Tareas entregadas a tiempo | E53: ='CÁLCULOS'!B7 -> Obj. 2 | F53: ='CÁLCULOS'!C7 -> 0.85 | G53: ='CÁLCULOS'!D7 -> 0.9 | H53: ● | I53: ● | J53: ● | K53: ='CÁLCULOS'!H7 -> 0.94444444 | P53: =UPPER('CÁLCULOS'!G7) -> EN RIESGO
B54: ='CÁLCULOS'!A8 -> Promedio general | E54: ='CÁLCULOS'!B8 -> Obj. 2 | F54: ='CÁLCULOS'!C8 -> 8.43 | G54: ='CÁLCULOS'!D8 -> 8.5 | H54: ● | I54: ● | J54: ● | K54: ='CÁLCULOS'!H8 -> 0.99176471 | P54: =UPPER('CÁLCULOS'!G8) -> EN RIESGO
B55: ='CÁLCULOS'!A9 -> Avance del plan profesional | E55: ='CÁLCULOS'!B9 -> Obj. 3 | F55: ='CÁLCULOS'!C9 -> 0.3 | G55: ='CÁLCULOS'!D9 -> 0.15 | H55: ● | I55: ● | J55: ● | K55: ='CÁLCULOS'!H9 -> 0.3 | P55: =UPPER('CÁLCULOS'!G9) -> EN META
B57: SEMÁFORO POR ASIGNATURA | L57: PROMEDIO POR ASIGNATURA (color según semáforo)
B58: Asignatura | D58: Parcial 1 | E58: Parcial 2 | F58: Parcial 3 / Final | G58: Promedio | H58: Variación | I58: Tareas a tiempo | J58: Semáforo | K58: Estado
B59: =REGISTRO!B36 -> Matemáticas | D59: =IF(REGISTRO!C36="","",REGISTRO!C36) -> 6.2 | E59: =IF(REGISTRO!D36="","",REGISTRO!D36) -> 7 | F59: =IF(REGISTRO!E36="","",REGISTRO!E36) | G59: =REGISTRO!F36 -> 6.6 | H59: =REGISTRO!G36 -> 0.8 | I59: =REGISTRO!G45 -> 0.7 | J59: ='CÁLCULOS'!F28 -> 1 | K59: ='CÁLCULOS'!G28 -> BAJO
B60: =REGISTRO!B37 -> Comunicación oral y escrita | D60: =IF(REGISTRO!C37="","",REGISTRO!C37) -> 8.9 | E60: =IF(REGISTRO!D37="","",REGISTRO!D37) -> 9.3 | F60: =IF(REGISTRO!E37="","",REGISTRO!E37) | G60: =REGISTRO!F37 -> 9.1 | H60: =REGISTRO!G37 -> 0.4 | I60: =REGISTRO!G46 -> 1 | J60: ='CÁLCULOS'!F29 -> 3 | K60: ='CÁLCULOS'!G29 -> EN META
B61: =REGISTRO!B38 -> Inglés | D61: =IF(REGISTRO!C38="","",REGISTRO!C38) -> 8 | E61: =IF(REGISTRO!D38="","",REGISTRO!D38) -> 7.8 | F61: =IF(REGISTRO!E38="","",REGISTRO!E38) | G61: =REGISTRO!F38 -> 7.9 | H61: =REGISTRO!G38 -> -0.2 | I61: =REGISTRO!G47 -> 0.77777778 | J61: ='CÁLCULOS'!F30 -> 2 | K61: ='CÁLCULOS'!G30 -> EN RIESGO
B62: =REGISTRO!B39 -> Tecnologías de información | D62: =IF(REGISTRO!C39="","",REGISTRO!C39) -> 8.8 | E62: =IF(REGISTRO!D39="","",REGISTRO!D39) -> 9.2 | F62: =IF(REGISTRO!E39="","",REGISTRO!E39) | G62: =REGISTRO!F39 -> 9 | H62: =REGISTRO!G39 -> 0.4 | I62: =REGISTRO!G48 -> 0.85714286 | J62: ='CÁLCULOS'!F31 -> 3 | K62: ='CÁLCULOS'!G31 -> EN META
B63: =REGISTRO!B40 -> Desarrollo humano | D63: =IF(REGISTRO!C40="","",REGISTRO!C40) -> 9.5 | E63: =IF(REGISTRO!D40="","",REGISTRO!D40) -> 9.6 | F63: =IF(REGISTRO!E40="","",REGISTRO!E40) | G63: =REGISTRO!F40 -> 9.55 | H63: =REGISTRO!G40 -> 0.1 | I63: =REGISTRO!G49 -> 1 | J63: ='CÁLCULOS'!F32 -> 3 | K63: ='CÁLCULOS'!G32 -> EN META
B64: =REGISTRO!B41 -> Promedio general (por evaluación) | D64: =IF(REGISTRO!C41="","",REGISTRO!C41) -> 8.28 | E64: =IF(REGISTRO!D41="","",REGISTRO!D41) -> 8.58 | F64: =IF(REGISTRO!E41="","",REGISTRO!E41) | G64: =REGISTRO!F41 -> 8.43 | H64: =REGISTRO!G41 -> 0.3 | I64: =REGISTRO!G50 -> 0.85 | J64: ='CÁLCULOS'!F8 -> 2 | K64: =CHOOSE('CÁLCULOS'!F8,"BAJO","EN RIESGO","EN META") -> EN RIESGO
B66: CÓMO LEER EL SEMÁFORO
B67: ● | C67: Verde · En meta: el indicador alcanza o supera la meta. Mantengo lo que estoy haciendo.
B68: ● | C68: Amarillo · En riesgo: estoy por debajo de la meta, pero arriba del mínimo. Necesito ajustar.
B69: ● | C69: Rojo · Bajo rendimiento: estoy por debajo del mínimo. Hago un plan de acción esa misma semana.
B70: Los datos salen de la hoja REGISTRO; las metas y los umbrales del semáforo también se ajustan ahí. Las barras de progreso muestran qué tan cerca estoy de cada meta (100 % = meta alcanzada).

Sheet CONCLUSIÓN
B2: Conclusión
B3: Lo que aprendí en la Etapa 2 y cómo me sirve para mi carrera profesional
B5: En la primera etapa definí mi meta, mi objetivo general y tres objetivos específicos con sus actividades. En esta segunda etapa me di cuenta de que un plan escrito no basta si no tengo una forma clara de saber si lo estoy cumpliendo. Por eso agregué a cada objetivo un indicador de desempeño y un KPI. El indicador me dice qué estoy haciendo en el día a día, por ejemplo cuántos días estudié en la semana. El KPI resume si voy logrando el resultado que me propuse, como cumplir al menos el 80 % de los bloques de estudio que planifiqué.
B7: Armar el tablero en Excel también me enseñó a ordenar la información antes de graficarla. Separé en hojas distintas los datos que registro cada semana, los cálculos y el tablero, para que todo se actualice cuando escribo un dato nuevo. Las gráficas de barras me muestran cómo cambian mis calificaciones de un parcial a otro y qué semanas cumplí mi horario; las gráficas circulares me dejan ver cuántas tareas entregué a tiempo; y las barras de progreso me recuerdan cuánto me falta para cada meta. Como dice Few (2006), un tablero sirve cuando deja ver lo importante en un solo vistazo, y eso fue lo que intenté lograr.
B9: Lo que más me sirvió fue el semáforo. Ver una materia en amarillo o en rojo me obliga a actuar antes del examen final, cuando todavía puedo pedir ayuda, repasar con preguntas y ejercicios (una de las técnicas de estudio con mejor respaldo, según Dunlosky et al., 2013) o reorganizar mi semana. También me ayuda a reconocer mis avances cuando un indicador pasa a verde, algo que en la Etapa 1 identifiqué como una necesidad. Con el tablero tomo decisiones a partir de datos y ya no solo con la sensación de que voy bien o mal.
B11: Para mi carrera profesional, esta etapa me deja herramientas que voy a seguir usando. En casi cualquier trabajo se habla de metas, indicadores y reportes, y saber diseñar un KPI, registrar datos y presentarlos con claridad es una habilidad que se puede aplicar en cualquier área. Además, dar seguimiento a mis propios objetivos fortalece la organización, la autonomía y la perseverancia, que son competencias que me propuse entrenar. Mi compromiso es actualizar el registro cada domingo, durante la revisión semanal de mi horario, y ajustar el plan cuando los datos me indiquen que algo no está funcionando.
B13: Un plan me dice a dónde quiero llegar; el tablero de control me dice si voy en camino.
B15: Valeria Ochoa · ID 5277522

Sheet REGISTRO
B1: REGISTRO DE DATOS · lo que capturo para alimentar el tablero
B2: Escribo solo en las celdas azul claro; el tablero, los semáforos y los gráficos se actualizan solos. IMPORTANTE: los números que aparecen ahora son DATOS DE EJEMPLO para mostrar cómo funciona el tablero. Hay que cambiarlos por mis materias, calificaciones y avances reales.
B3: Celda de captura | C3: Celda con fórmula (no se edita)
B4: 1. PARÁMETROS Y METAS
B5: Fecha de corte del reporte (la actualizo cada domingo) | C5: 46320
B6: Inicio del plan (lunes de la semana 1) | C6: 46265
B7: Duración del plan de desarrollo profesional (meses) | C7: 12
B8: Meses transcurridos del plan | C8: =ROUND(MAX(0,(C5-C6)/30.44),1) -> 1.8
B9: Avance esperado del plan profesional a la fecha | C9: =MIN(1,C8/C7) -> 0.15
B11: Indicador | C11: Verde: en meta desde | D11: Amarillo: en riesgo desde | E11: Rojo: bajo rendimiento
B12: Cumplimiento del horario (Obj. 1) | C12: 0.8 | D12: 0.6 | E12: =D12 -> 0.6
B13: Días de estudio por semana (Obj. 1) | C13: 5 | D13: 4 | E13: =D13 -> 4
B14: Tareas entregadas a tiempo (Obj. 2) | C14: 0.9 | D14: 0.75 | E14: =D14 -> 0.75
B15: Promedio de calificaciones, escala 0 a 10 (Obj. 2) | C15: 8.5 | D15: 7 | E15: =D15 -> 7
B16: Avance del plan profesional vs. avance esperado (Obj. 3) | C16: 1 | D16: 0.7 | E16: =D16 -> 0.7
B18: 2. OBJETIVO 1 · HORARIO SEMANAL DE ESTUDIO (12 semanas)
B19: Semana | C19: Inicio de semana | D19: Bloques planificados | E19: Bloques realizados | F19: Días de estudio | G19: ¿Revisé el horario el domingo? | H19: % de cumplimiento | I19: Estado
B20: Semana 1 | C20: =$C$6+7*0 -> 46265 | D20: 10 | E20: 5 | F20: 3 | G20: No | H20: =IF(OR(E20="",D20=0),"",E20/D20) -> 0.5 | I20: =IF(H20="","Pendiente",IF(H20>=$C$12,"En meta",IF(H20>=$D$12,"En riesgo","Bajo rendimiento"))) -> Bajo rendimiento
B21: Semana 2 | C21: =$C$6+7*1 -> 46272 | D21: 10 | E21: 7 | F21: 4 | G21: Sí | H21: =IF(OR(E21="",D21=0),"",E21/D21) -> 0.7 | I21: =IF(H21="","Pendiente",IF(H21>=$C$12,"En meta",IF(H21>=$D$12,"En riesgo","Bajo rendimiento"))) -> En riesgo
B22: Semana 3 | C22: =$C$6+7*2 -> 46279 | D22: 10 | E22: 8 | F22: 5 | G22: Sí | H22: =IF(OR(E22="",D22=0),"",E22/D22) -> 0.8 | I22: =IF(H22="","Pendiente",IF(H22>=$C$12,"En meta",IF(H22>=$D$12,"En riesgo","Bajo rendimiento"))) -> En meta
B23: Semana 4 | C23: =$C$6+7*3 -> 46286 | D23: 10 | E23: 9 | F23: 5 | G23: Sí | H23: =IF(OR(E23="",D23=0),"",E23/D23) -> 0.9 | I23: =IF(H23="","Pendiente",IF(H23>=$C$12,"En meta",IF(H23>=$D$12,"En riesgo","Bajo rendimiento"))) -> En meta
B24: Semana 5 | C24: =$C$6+7*4 -> 46293 | D24: 10 | E24: 7 | F24: 4 | G24: No | H24: =IF(OR(E24="",D24=0),"",E24/D24) -> 0.7 | I24: =IF(H24="","Pendiente",IF(H24>=$C$12,"En meta",IF(H24>=$D$12,"En riesgo","Bajo rendimiento"))) -> En riesgo
B25: Semana 6 | C25: =$C$6+7*5 -> 46300 | D25: 10 | E25: 9 | F25: 5 | G25: Sí | H25: =IF(OR(E25="",D25=0),"",E25/D25) -> 0.9 | I25: =IF(H25="","Pendiente",IF(H25>=$C$12,"En meta",IF(H25>=$D$12,"En riesgo","Bajo rendimiento"))) -> En meta
B26: Semana 7 | C26: =$C$6+7*6 -> 46307 | D26: 10 | E26: 10 | F26: 5 | G26: Sí | H26: =IF(OR(E26="",D26=0),"",E26/D26) -> 1 | I26: =IF(H26="","Pendiente",IF(H26>=$C$12,"En meta",IF(H26>=$D$12,"En riesgo","Bajo rendimiento"))) -> En meta
B27: Semana 8 | C27: =$C$6+7*7 -> 46314 | D27: 10 | E27: 10 | F27: 5 | G27: Sí | H27: =IF(OR(E27="",D27=0),"",E27/D27) -> 1 | I27: =IF(H27="","Pendiente",IF(H27>=$C$12,"En meta",IF(H27>=$D$12,"En riesgo","Bajo rendimiento"))) -> En meta
B28: Semana 9 | C28: =$C$6+7*8 -> 46321 | D28: 10 | H28: =IF(OR(E28="",D28=0),"",E28/D28) | I28: =IF(H28="","Pendiente",IF(H28>=$C$12,"En meta",IF(H28>=$D$12,"En riesgo","Bajo rendimiento"))) -> Pendiente
B29: Semana 10 | C29: =$C$6+7*9 -> 46328 | D29: 10 | H29: =IF(OR(E29="",D29=0),"",E29/D29) | I29: =IF(H29="","Pendiente",IF(H29>=$C$12,"En meta",IF(H29>=$D$12,"En riesgo","Bajo rendimiento"))) -> Pendiente
B30: Semana 11 | C30: =$C$6+7*10 -> 46335 | D30: 10 | H30: =IF(OR(E30="",D30=0),"",E30/D30) | I30: =IF(H30="","Pendiente",IF(H30>=$C$12,"En meta",IF(H30>=$D$12,"En riesgo","Bajo rendimiento"))) -> Pendiente
B31: Semana 12 | C31: =$C$6+7*11 -> 46342 | D31: 10 | H31: =IF(OR(E31="",D31=0),"",E31/D31) | I31: =IF(H31="","Pendiente",IF(H31>=$C$12,"En meta",IF(H31>=$D$12,"En riesgo","Bajo rendimiento"))) -> Pendiente
B32: Total de las semanas registradas | C32: =COUNT(E20:E31)&" de 12" -> 8 de 12 | D32: =SUMPRODUCT((E20:E31<>"")*D20:D31) -> 80 | E32: =SUM(E20:E31) -> 65 | F32: =IFERROR(AVERAGE(F20:F31),0) -> 4.5 | G32: =COUNTIF(G20:G31,"Sí") -> 6 | H32: =IF(D32=0,0,E32/D32) -> 0.8125 | I32: =IF(H32>=$C$12,"En meta",IF(H32>=$D$12,"En riesgo","Bajo rendimiento")) -> En meta
B34: 3. OBJETIVO 2 · CALIFICACIONES POR ASIGNATURA (escala 0 a 10)
B35: Asignatura | C35: Parcial 1 | D35: Parcial 2 | E35: Parcial 3 / Final | F35: Promedio | G35: Variación (último parcial − parcial 1) | H35: Estado
B36: Matemáticas | C36: 6.2 | D36: 7 | F36: =IF(COUNT(C36:E36)=0,"",AVERAGE(C36:E36)) -> 6.6 | G36: =IFERROR(IF(COUNT(C36:E36)<2,"",IF(E36<>"",E36,D36)-C36),"") -> 0.8 | H36: =IF(F36="","Pendiente",IF(F36>=$C$15,"En meta",IF(F36>=$D$15,"En riesgo","Bajo rendimiento"))) -> Bajo rendimiento
B37: Comunicación oral y escrita | C37: 8.9 | D37: 9.3 | F37: =IF(COUNT(C37:E37)=0,"",AVERAGE(C37:E37)) -> 9.1 | G37: =IFERROR(IF(COUNT(C37:E37)<2,"",IF(E37<>"",E37,D37)-C37),"") -> 0.4 | H37: =IF(F37="","Pendiente",IF(F37>=$C$15,"En meta",IF(F37>=$D$15,"En riesgo","Bajo rendimiento"))) -> En meta
B38: Inglés | C38: 8 | D38: 7.8 | F38: =IF(COUNT(C38:E38)=0,"",AVERAGE(C38:E38)) -> 7.9 | G38: =IFERROR(IF(COUNT(C38:E38)<2,"",IF(E38<>"",E38,D38)-C38),"") -> -0.2 | H38: =IF(F38="","Pendiente",IF(F38>=$C$15,"En meta",IF(F38>=$D$15,"En riesgo","Bajo rendimiento"))) -> En riesgo
B39: Tecnologías de información | C39: 8.8 | D39: 9.2 | F39: =IF(COUNT(C39:E39)=0,"",AVERAGE(C39:E39)) -> 9 | G39: =IFERROR(IF(COUNT(C39:E39)<2,"",IF(E39<>"",E39,D39)-C39),"") -> 0.4 | H39: =IF(F39="","Pendiente",IF(F39>=$C$15,"En meta",IF(F39>=$D$15,"En riesgo","Bajo rendimiento"))) -> En meta
B40: Desarrollo humano | C40: 9.5 | D40: 9.6 | F40: =IF(COUNT(C40:E40)=0,"",AVERAGE(C40:E40)) -> 9.55 | G40: =IFERROR(IF(COUNT(C40:E40)<2,"",IF(E40<>"",E40,D40)-C40),"") -> 0.1 | H40: =IF(F40="","Pendiente",IF(F40>=$C$15,"En meta",IF(F40>=$D$15,"En riesgo","Bajo rendimiento"))) -> En meta
B41: Promedio general (por evaluación) | C41: =IFERROR(AVERAGE(C36:C40),"") -> 8.28 | D41: =IFERROR(AVERAGE(D36:D40),"") -> 8.58 | E41: =IFERROR(AVERAGE(E36:E40),"") | F41: =IFERROR(AVERAGE(F36:F40),0) -> 8.43 | G41: =IFERROR(IF(COUNT(C41:E41)<2,"",IF(E41<>"",E41,D41)-C41),"") -> 0.3 | H41: =IF(F41>=$C$15,"En meta",IF(F41>=$D$15,"En riesgo","Bajo rendimiento")) -> En riesgo
B43: 4. OBJETIVO 2 · ENTREGA DE TAREAS
B44: Asignatura | C44: Tareas asignadas | D44: Entregadas a tiempo | E44: Entregadas con retraso | F44: No entregadas | G44: % a tiempo | H44: Estado
...

Sheet CÁLCULOS
A1: CÁLCULOS AUXILIARES · alimentan el tablero y los gráficos (no se editan)
A2: Código del semáforo: 3 = verde (en meta) · 2 = amarillo (en riesgo) · 1 = rojo (bajo rendimiento). En el objetivo 3 la meta a la fecha es el avance esperado según los meses transcurridos.
A4: Indicador | B4: Objetivo | C4: Valor actual | D4: Meta (verde desde) | E4: Amarillo desde | F4: Código | G4: Estado | H4: Progreso hacia la meta | I4: Cómo se calcula
A5: Cumplimiento del horario | B5: Obj. 1 | C5: =REGISTRO!H32 -> 0.8125 | D5: =REGISTRO!C12 -> 0.8 | E5: =REGISTRO!D12 -> 0.6 | F5: =IF(C5>=D5,3,IF(C5>=E5,2,1)) -> 3 | G5: =CHOOSE(F5,"Bajo rendimiento","En riesgo","En meta") -> En meta | H5: =IF(D5=0,0,MIN(1,MAX(0,C5/D5))) -> 1 | I5: Bloques realizados ÷ bloques planificados (semanas registradas)
A6: Días de estudio por semana | B6: Obj. 1 | C6: =REGISTRO!F32 -> 4.5 | D6: =REGISTRO!C13 -> 5 | E6: =REGISTRO!D13 -> 4 | F6: =IF(C6>=D6,3,IF(C6>=E6,2,1)) -> 2 | G6: =CHOOSE(F6,"Bajo rendimiento","En riesgo","En meta") -> En riesgo | H6: =IF(D6=0,0,MIN(1,MAX(0,C6/D6))) -> 0.9 | I6: Promedio de días con al menos un bloque de estudio
A7: Tareas entregadas a tiempo | B7: Obj. 2 | C7: =REGISTRO!G50 -> 0.85 | D7: =REGISTRO!C14 -> 0.9 | E7: =REGISTRO!D14 -> 0.75 | F7: =IF(C7>=D7,3,IF(C7>=E7,2,1)) -> 2 | G7: =CHOOSE(F7,"Bajo rendimiento","En riesgo","En meta") -> En riesgo | H7: =IF(D7=0,0,MIN(1,MAX(0,C7/D7))) -> 0.94444444 | I7: Tareas entregadas en fecha ÷ tareas asignadas
A8: Promedio general | B8: Obj. 2 | C8: =REGISTRO!F41 -> 8.43 | D8: =REGISTRO!C15 -> 8.5 | E8: =REGISTRO!D15 -> 7 | F8: =IF(C8>=D8,3,IF(C8>=E8,2,1)) -> 2 | G8: =CHOOSE(F8,"Bajo rendimiento","En riesgo","En meta") -> En riesgo | H8: =IF(D8=0,0,MIN(1,MAX(0,C8/D8))) -> 0.99176471 | I8: Promedio de los promedios por asignatura (0 a 10)
A9: Avance del plan profesional | B9: Obj. 3 | C9: =REGISTRO!E60 -> 0.3 | D9: =REGISTRO!C9 -> 0.15 | E9: =REGISTRO!D16 -> 0.7 | F9: =IF(D9=0,3,IF(C9/D9>=REGISTRO!C16,3,IF(C9/D9>=E9,2,1))) -> 3 | G9: =CHOOSE(F9,"Bajo rendimiento","En riesgo","En meta") -> En meta | H9: =MIN(1,MAX(0,C9)) -> 0.3 | I9: Promedio del avance de los hitos; se compara con el avance esperado a la fecha
A12: Semana | B12: En meta | C12: En riesgo | D12: Bajo rendimiento | E12: Meta
A13: Sem 1 | B13: =IF(REGISTRO!$H20="",0,IF(REGISTRO!$H20>=REGISTRO!$C$12,REGISTRO!$H20,0)) -> 0 | C13: =IF(REGISTRO!$H20="",0,IF(AND(REGISTRO!$H20<REGISTRO!$C$12,REGISTRO!$H20>=REGISTRO!$D$12),REGISTRO!$H20,0)) -> 0 | D13: =IF(REGISTRO!$H20="",0,IF(REGISTRO!$H20<REGISTRO!$D$12,REGISTRO!$H20,0)) -> 0.5 | E13: =REGISTRO!$C$12 -> 0.8
A14: Sem 2 | B14: =IF(REGISTRO!$H21="",0,IF(REGISTRO!$H21>=REGISTRO!$C$12,REGISTRO!$H21,0)) -> 0 | C14: =IF(REGISTRO!$H21="",0,IF(AND(REGISTRO!$H21<REGISTRO!$C$12,REGISTRO!$H21>=REGISTRO!$D$12),REGISTRO!$H21,0)) -> 0.7 | D14: =IF(REGISTRO!$H21="",0,IF(REGISTRO!$H21<REGISTRO!$D$12,REGISTRO!$H21,0)) -> 0 | E14: =REGISTRO!$C$12 -> 0.8
A15: Sem 3 | B15: =IF(REGISTRO!$H22="",0,IF(REGISTRO!$H22>=REGISTRO!$C$12,REGISTRO!$H22,0)) -> 0.8 | C15: =IF(REGISTRO!$H22="",0,IF(AND(REGISTRO!$H22<REGISTRO!$C$12,REGISTRO!$H22>=REGISTRO!$D$12),REGISTRO!$H22,0)) -> 0 | D15: =IF(REGISTRO!$H22="",0,IF(REGISTRO!$H22<REGISTRO!$D$12,REGISTRO!$H22,0)) -> 0 | E15: =REGISTRO!$C$12 -> 0.8
A16: Sem 4 | B16: =IF(REGISTRO!$H23="",0,IF(REGISTRO!$H23>=REGISTRO!$C$12,REGISTRO!$H23,0)) -> 0.9 | C16: =IF(REGISTRO!$H23="",0,IF(AND(REGISTRO!$H23<REGISTRO!$C$12,REGISTRO!$H23>=REGISTRO!$D$12),REGISTRO!$H23,0)) -> 0 | D16: =IF(REGISTRO!$H23="",0,IF(REGISTRO!$H23<REGISTRO!$D$12,REGISTRO!$H23,0)) -> 0 | E16: =REGISTRO!$C$12 -> 0.8
A17: Sem 5 | B17: =IF(REGISTRO!$H24="",0,IF(REGISTRO!$H24>=REGISTRO!$C$12,REGISTRO!$H24,0)) -> 0 | C17: =IF(REGISTRO!$H24="",0,IF(AND(REGISTRO!$H24<REGISTRO!$C$12,REGISTRO!$H24>=REGISTRO!$D$12),REGISTRO!$H24,0)) -> 0.7 | D17: =IF(REGISTRO!$H24="",0,IF(REGISTRO!$H24<REGISTRO!$D$12,REGISTRO!$H24,0)) -> 0 | E17: =REGISTRO!$C$12 -> 0.8
A18: Sem 6 | B18: =IF(REGISTRO!$H25="",0,IF(REGISTRO!$H25>=REGISTRO!$C$12,REGISTRO!$H25,0)) -> 0.9 | C18: =IF(REGISTRO!$H25="",0,IF(AND(REGISTRO!$H25<REGISTRO!$C$12,REGISTRO!$H25>=REGISTRO!$D$12),REGISTRO!$H25,0)) -> 0 | D18: =IF(REGISTRO!$H25="",0,IF(REGISTRO!$H25<REGISTRO!$D$12,REGISTRO!$H25,0)) -> 0 | E18: =REGISTRO!$C$12 -> 0.8
A19: Sem 7 | B19: =IF(REGISTRO!$H26="",0,IF(REGISTRO!$H26>=REGISTRO!$C$12,REGISTRO!$H26,0)) -> 1 | C19: =IF(REGISTRO!$H26="",0,IF(AND(REGISTRO!$H26<REGISTRO!$C$12,REGISTRO!$H26>=REGISTRO!$D$12),REGISTRO!$H26,0)) -> 0 | D19: =IF(REGISTRO!$H26="",0,IF(REGISTRO!$H26<REGISTRO!$D$12,REGISTRO!$H26,0)) -> 0 | E19: =REGISTRO!$C$12 -> 0.8
A20: Sem 8 | B20: =IF(REGISTRO!$H27="",0,IF(REGISTRO!$H27>=REGISTRO!$C$12,REGISTRO!$H27,0)) -> 1 | C20: =IF(REGISTRO!$H27="",0,IF(AND(REGISTRO!$H27<REGISTRO!$C$12,REGISTRO!$H27>=REGISTRO!$D$12),REGISTRO!$H27,0)) -> 0 | D20: =IF(REGISTRO!$H27="",0,IF(REGISTRO!$H27<REGISTRO!$D$12,REGISTRO!$H27,0)) -> 0 | E20: =REGISTRO!$C$12 -> 0.8
A21: Sem 9 | B21: =IF(REGISTRO!$H28="",0,IF(REGISTRO!$H28>=REGISTRO!$C$12,REGISTRO!$H28,0)) -> 0 | C21: =IF(REGISTRO!$H28="",0,IF(AND(REGISTRO!$H28<REGISTRO!$C$12,REGISTRO!$H28>=REGISTRO!$D$12),REGISTRO!$H28,0)) -> 0 | D21: =IF(REGISTRO!$H28="",0,IF(REGISTRO!$H28<REGISTRO!$D$12,REGISTRO!$H28,0)) -> 0 | E21: =REGISTRO!$C$12 -> 0.8
A22: Sem 10 | B22: =IF(REGISTRO!$H29="",0,IF(REGISTRO!$H29>=REGISTRO!$C$12,REGISTRO!$H29,0)) -> 0 | C22: =IF(REGISTRO!$H29="",0,IF(AND(REGISTRO!$H29<REGISTRO!$C$12,REGISTRO!$H29>=REGISTRO!$D$12),REGISTRO!$H29,0)) -> 0 | D22: =IF(REGISTRO!$H29="",0,IF(REGISTRO!$H29<REGISTRO!$D$12,REGISTRO!$H29,0)) -> 0 | E22: =REGISTRO!$C$12 -> 0.8
A23: Sem 11 | B23: =IF(REGISTRO!$H30="",0,IF(REGISTRO!$H30>=REGISTRO!$C$12,REGISTRO!$H30,0)) -> 0 | C23: =IF(REGISTRO!$H30="",0,IF(AND(REGISTRO!$H30<REGISTRO!$C$12,REGISTRO!$H30>=REGISTRO!$D$12),REGISTRO!$H30,0)) -> 0 | D23: =IF(REGISTRO!$H30="",0,IF(REGISTRO!$H30<REGISTRO!$D$12,REGISTRO!$H30,0)) -> 0 | E23: =REGISTRO!$C$12 -> 0.8
A24: Sem 12 | B24: =IF(REGISTRO!$H31="",0,IF(REGISTRO!$H31>=REGISTRO!$C$12,REGISTRO!$H31,0)) -> 0 | C24: =IF(REGISTRO!$H31="",0,IF(AND(REGISTRO!$H31<REGISTRO!$C$12,REGISTRO!$H31>=REGISTRO!$D$12),REGISTRO!$H31,0)) -> 0 | D24: =IF(REGISTRO!$H31="",0,IF(REGISTRO!$H31<REGISTRO!$D$12,REGISTRO!$H31,0)) -> 0 | E24: =REGISTRO!$C$12 -> 0.8
A27: Asignatura | B27: En meta | C27: En riesgo | D27: Bajo rendimiento | E27: Meta de promedio | F27: Código | G27: Estado
A28: =REGISTRO!B36 -> Matemáticas | B28: =IF(REGISTRO!$F36="",0,IF(REGISTRO!$F36>=REGISTRO!$C$15,REGISTRO!$F36,0)) -> 0 | C28: =IF(REGISTRO!$F36="",0,IF(AND(REGISTRO!$F36<REGISTRO!$C$15,REGISTRO!$F36>=REGISTRO!$D$15),REGISTRO!$F36,0)) -> 0 | D28: =IF(REGISTRO!$F36="",0,IF(REGISTRO!$F36<REGISTRO!$D$15,REGISTRO!$F36,0)) -> 6.6 | E28: =REGISTRO!$C$15 -> 8.5 | F28: =IF(REGISTRO!$F36="",0,IF(REGISTRO!$F36>=REGISTRO!$C$15,3,IF(REGISTRO!$F36>=REGISTRO!$D$15,2,1))) -> 1 | G28: =CHOOSE(F28+1,"PENDIENTE","BAJO","EN RIESGO","EN META") -> BAJO
A29: =REGISTRO!B37 -> Comunicación oral y escrita | B29: =IF(REGISTRO!$F37="",0,IF(REGISTRO!$F37>=REGISTRO!$C$15,REGISTRO!$F37,0)) -> 9.1 | C29: =IF(REGISTRO!$F37="",0,IF(AND(REGISTRO!$F37<REGISTRO!$C$15,REGISTRO!$F37>=REGISTRO!$D$15),REGISTRO!$F37,0)) -> 0 | D29: =IF(REGISTRO!$F37="",0,IF(REGISTRO!$F37<REGISTRO!$D$15,REGISTRO!$F37,0)) -> 0 | E29: =REGISTRO!$C$15 -> 8.5 | F29: =IF(REGISTRO!$F37="",0,IF(REGISTRO!$F37>=REGISTRO!$C$15,3,IF(REGISTRO!$F37>=REGISTRO!$D$15,2,1))) -> 3 | G29: =CHOOSE(F29+1,"PENDIENTE","BAJO","EN RIESGO","EN META") -> EN META
A30: =REGISTRO!B38 -> Inglés | B30: =IF(REGISTRO!$F38="",0,IF(REGISTRO!$F38>=REGISTRO!$C$15,REGISTRO!$F38,0)) -> 0 | C30: =IF(REGISTRO!$F38="",0,IF(AND(REGISTRO!$F38<REGISTRO!$C$15,REGISTRO!$F38>=REGISTRO!$D$15),REGISTRO!$F38,0)) -> 7.9 | D30: =IF(REGISTRO!$F38="",0,IF(REGISTRO!$F38<REGISTRO!$D$15,REGISTRO!$F38,0)) -> 0 | E30: =REGISTRO!$C$15 -> 8.5 | F30: =IF(REGISTRO!$F38="",0,IF(REGISTRO!$F38>=REGISTRO!$C$15,3,IF(REGISTRO!$F38>=REGISTRO!$D$15,2,1))) -> 2 | G30: =CHOOSE(F30+1,"PENDIENTE","BAJO","EN RIESGO","EN META") -> EN RIESGO
A31: =REGISTRO!B39 -> Tecnologías de información | B31: =IF(REGISTRO!$F39="",0,IF(REGISTRO!$F39>=REGISTRO!$C$15,REGISTRO!$F39,0)) -> 9 | C31: =IF(REGISTRO!$F39="",0,IF(AND(REGISTRO!$F39<REGISTRO!$C$15,REGISTRO!$F39>=REGISTRO!$D$15),REGISTRO!$F39,0)) -> 0 | D31: =IF(REGISTRO!$F39="",0,IF(REGISTRO!$F39<REGISTRO!$D$15,REGISTRO!$F39,0)) -> 0 | E31: =REGISTRO!$C$15 -> 8.5 | F31: =IF(REGISTRO!$F39="",0,IF(REGISTRO!$F39>=REGISTRO!$C$15,3,IF(REGISTRO!$F39>=REGISTRO!$D$15,2,1))) -> 3 | G31: =CHOOSE(F31+1,"PENDIENTE","BAJO","EN RIESGO","EN META") -> EN META
A32: =REGISTRO!B40 -> Desarrollo humano | B32: =IF(REGISTRO!$F40="",0,IF(REGISTRO!$F40>=REGISTRO!$C$15,REGISTRO!$F40,0)) -> 9.55 | C32: =IF(REGISTRO!$F40="",0,IF(AND(REGISTRO!$F40<REGISTRO!$C$15,REGISTRO!$F40>=REGISTRO!$D$15),REGISTRO!$F40,0)) -> 0 | D32: =IF(REGISTRO!$F40="",0,IF(REGISTRO!$F40<REGISTRO!$D$15,REGISTRO!$F40,0)) -> 0 | E32: =REGISTRO!$C$15 -> 8.5 | F32: =IF(REGISTRO!$F40="",0,IF(REGISTRO!$F40>=REGISTRO!$C$15,3,IF(REGISTRO!$F40>=REGISTRO!$D$15,2,1))) -> 3 | G32: =CHOOSE(F32+1,"PENDIENTE","BAJO","EN RIESGO","EN META") -> EN META
A35: Estado de las tareas | B35: Cantidad
A36: A tiempo | B36: =REGISTRO!D50 -> 34
A37: Con retraso | B37: =REGISTRO!E50 -> 4
A38: No entregadas | B38: =REGISTRO!F50 -> 2
A41: Estado de los hitos | B41: Cantidad
A42: Completados | B42: =COUNTIF(REGISTRO!F54:F59,"Completado") -> 1
A43: En proceso | B43: =COUNTIF(REGISTRO!F54:F59,"En proceso") -> 2
A44: Pendientes | B44: =COUNTIF(REGISTRO!F54:F59,"Pendiente") -> 3
A47: Indicador de desempeño · Obj. 3 | B47: Valor
A48: Cursos completados | B48: =COUNTIFS(REGISTRO!C54:C59,"Curso",REGISTRO!E54:E59,">=1")&" de "&COUNTIF(REGISTRO!C54:C59,"Curso") -> 0 de 1
A49: Currículum actualizado | B49: =IF(COUNTIFS(REGISTRO!C54:C59,"Currículum",REGISTRO!E54:E59,">=1")>0,"Sí","En proceso") -> En proceso
A50: Eventos asistidos | B50: =COUNTIFS(REGISTRO!C54:C59,"Evento",REGISTRO!E54:E59,">=1")&" de "&COUNTIF(REGISTRO!C54:C59,"Evento") -> 0 de 2

Sheet REFERENCIAS
B2: Referencias
B4: Dunlosky, J., Rawson, K. A., Marsh, E. J., Nathan, M. J., & Willingham, D. T. (2013). Improving students’ learning with effective learning techniques: Promising directions from cognitive and educational psychology. Psychological Science in the Public Interest, 14(1), 4–58. https://doi.org/10.1177/1529100612453266
B5: Few, S. (2006). Information dashboard design: The effective visual communication of data. O’Reilly Media.
B6: Parmenter, D. (2015). Key performance indicators: Developing, implementing, and using winning KPIs (3rd ed.). John Wiley & Sons.
B8: Videos de apoyo del curso que revisé (YouTube)
B9: https://www.youtube.com/watch?v=830NHbvbo5g
B10: https://www.youtube.com/watch?v=Oanr41Tz28U
B11: https://www.youtube.com/watch?v=Pfi1kE2tYBs
B12: https://www.youtube.com/watch?v=D3kV5dMn5fk
B13: https://www.youtube.com/watch?v=1SEOOoMEm78
