Workbook

Sheet ENCABEZADO
A1: PROYECTO INTEGRADOR – ETAPA 2
A2: Tablero de control de mi plan de carrera
A4: [Logotipo de la institución: Insertar > Imágenes]
A8: Estudiante | B8: Valeria Ochoa
A9: ID | B9: 5277522
A10: Institución | B10: Universidad Autónoma de Guadalajara
A11: Carrera | B11: (completar)
A12: Materia | B12: (completar)
A13: Docente | B13: (completar)
A14: Actividad | B14: Proyecto integrador – Etapa 2: tablero de control
A15: Fecha de entrega | B15: 46320
A17: Plan de carrera: meta, objetivos, actividades, indicadores de desempeño y KPI
A18: Tabla de la Etapa 1 con dos columnas nuevas: Indicador de desempeño y KPI (una por cada objetivo específico).
A19: Meta | B19: Objetivo general | C19: Objetivos específicos | D19: Actividades | E19: Indicador de desempeño (nuevo) | F19: KPI (nuevo)
A20: Concluir mi carrera y prepararme para oportunidades laborales. | B20: Mejorar mi rendimiento y mis competencias en 12 meses mediante planificación y hábitos sostenibles. | C20: Objetivo 1. Organizar y cumplir un horario semanal de estudio en 3 meses. Plazo: semanal, durante 3 meses. | D20: 1.1 Crear un calendario semanal con clases, entregas y tiempo de estudio. 1.2 Estudiar al menos 5 días por semana en bloques de 45–60 minutos. 1.3 Revisar cada domingo las tareas completadas y ajustar el horario. | E20: Constancia en el estudio: días a la semana en los que hago al menos un bloque de estudio de 45–60 min. Meta: 5 días por semana. Se registra cada semana, en la revisión del domingo. | F20: % de cumplimiento del horario = bloques realizados ÷ bloques planificados × 100. Meta: 80 % o más. Semáforo: verde 80 % o más; amarillo 60–79 %; rojo menos de 60 %.
C21: Objetivo 2. Mejorar mi desempeño académico en las asignaturas del semestre. Plazo: semestral. | D21: 2.1 Identificar al inicio del mes las asignaturas y temas que me resultan más difíciles. 2.2 Realizar ejercicios o preguntas de repaso al menos dos veces por semana por asignatura prioritaria. 2.3 Consultar al docente o a un compañero cuando una duda continúe después de estudiar. | E21: Evolución de mis calificaciones: promedio por asignatura en cada evaluación (parcial 1, parcial 2 y final) y su variación entre parciales. Meta: promedio general de 8.5 o más y variación positiva. Se registra después de cada evaluación. | F21: % de tareas entregadas a tiempo = tareas entregadas en fecha ÷ tareas asignadas × 100. Meta: 90 % o más. Semáforo: verde 90 % o más; amarillo 75–89 %; rojo menos de 75 %.
C22: Objetivo 3. Desarrollar competencias útiles para mi futuro profesional durante los próximos 12 meses. Plazo: 6 a 12 meses. | D22: 3.1 Completar al menos un curso, taller o capacitación relacionada con mi carrera. 3.2 Actualizar mi currículum con los estudios, proyectos y habilidades adquiridas. 3.3 Participar en al menos dos charlas, eventos académicos o actividades de contacto profesional. | E22: Acciones de desarrollo profesional: cursos completados, currículum actualizado (sí / no) y charlas o eventos a los que asistí. Meta: 1 curso, currículum actualizado y 2 eventos. Se registra cada mes. | F22: % de avance del plan profesional = promedio del avance de los 6 hitos del plan, comparado con el avance esperado a la fecha. Meta: 100 % a los 12 meses. Semáforo: verde si voy al día o adelantado; amarillo 70 % o más de lo esperado; rojo menos de 70 %.
A24: Indicador de desempeño: mide cómo voy con las actividades del día a día. KPI: es el resultado clave de cada objetivo; tiene fórmula, meta y semáforo (Parmenter, 2015). Los valores actuales están en la hoja TABLERO DE CONTROL.

Sheet TABLERO DE CONTROL
A1: TABLERO DE CONTROL: RENDIMIENTO ACADÉMICO
A2: Valeria Ochoa – ID 5277522 – Proyecto integrador, Etapa 2
A3: Fecha de corte: | B3: =DATOS!B5 -> 46320 | C3: Semanas registradas: | E3: =COUNT(DATOS!D21:D32)&" de 12" -> 8 de 12
A5: Indicadores clave (KPI)
A6: Indicador | B6: Objetivo | C6: Valor actual | D6: Meta | E6: Semáforo | F6: Estado | G6: Progreso hacia la meta
A7: =DATOS!A68 -> Cumplimiento del horario | B7: =DATOS!B68 -> Obj. 1 | C7: =DATOS!C68 -> 0.8125 | D7: =DATOS!D68 -> 0.8 | E7: =DATOS!F68 -> 3 | F7: =DATOS!G68 -> En meta | G7: =DATOS!H68 -> 1
A8: =DATOS!A69 -> Días de estudio por semana | B8: =DATOS!B69 -> Obj. 1 | C8: =DATOS!C69 -> 4.5 | D8: =DATOS!D69 -> 5 | E8: =DATOS!F69 -> 2 | F8: =DATOS!G69 -> En riesgo | G8: =DATOS!H69 -> 0.9
A9: =DATOS!A70 -> Tareas entregadas a tiempo | B9: =DATOS!B70 -> Obj. 2 | C9: =DATOS!C70 -> 0.85 | D9: =DATOS!D70 -> 0.9 | E9: =DATOS!F70 -> 2 | F9: =DATOS!G70 -> En riesgo | G9: =DATOS!H70 -> 0.94444444
A10: =DATOS!A71 -> Promedio general | B10: =DATOS!B71 -> Obj. 2 | C10: =DATOS!C71 -> 8.43 | D10: =DATOS!D71 -> 8.5 | E10: =DATOS!F71 -> 2 | F10: =DATOS!G71 -> En riesgo | G10: =DATOS!H71 -> 0.99176471
A11: =DATOS!A72 -> Avance del plan profesional | B11: =DATOS!B72 -> Obj. 3 | C11: =DATOS!C72 -> 0.3 | D11: =DATOS!D72 -> 0.15 | E11: =DATOS!F72 -> 3 | F11: =DATOS!G72 -> En meta | G11: =DATOS!H72 -> 0.3
A13: Semáforo por asignatura
A14: Asignatura | B14: Parcial 1 | C14: Parcial 2 | D14: Parcial 3 / Final | E14: Promedio | F14: Variación | G14: Tareas a tiempo | H14: Semáforo | I14: Estado
A15: =DATOS!A37 -> Matemáticas | B15: =IF(DATOS!B37="","",DATOS!B37) -> 6.2 | C15: =IF(DATOS!C37="","",DATOS!C37) -> 7 | D15: =IF(DATOS!D37="","",DATOS!D37) | E15: =DATOS!E37 -> 6.6 | F15: =DATOS!F37 -> 0.8 | G15: =DATOS!F46 -> 0.7 | H15: =DATOS!B90 -> 1 | I15: =DATOS!C90 -> Bajo rendimiento
A16: =DATOS!A38 -> Comunicación oral y escrita | B16: =IF(DATOS!B38="","",DATOS!B38) -> 8.9 | C16: =IF(DATOS!C38="","",DATOS!C38) -> 9.3 | D16: =IF(DATOS!D38="","",DATOS!D38) | E16: =DATOS!E38 -> 9.1 | F16: =DATOS!F38 -> 0.4 | G16: =DATOS!F47 -> 1 | H16: =DATOS!B91 -> 3 | I16: =DATOS!C91 -> En meta
A17: =DATOS!A39 -> Inglés | B17: =IF(DATOS!B39="","",DATOS!B39) -> 8 | C17: =IF(DATOS!C39="","",DATOS!C39) -> 7.8 | D17: =IF(DATOS!D39="","",DATOS!D39) | E17: =DATOS!E39 -> 7.9 | F17: =DATOS!F39 -> -0.2 | G17: =DATOS!F48 -> 0.77777778 | H17: =DATOS!B92 -> 2 | I17: =DATOS!C92 -> En riesgo
A18: =DATOS!A40 -> Tecnologías de información | B18: =IF(DATOS!B40="","",DATOS!B40) -> 8.8 | C18: =IF(DATOS!C40="","",DATOS!C40) -> 9.2 | D18: =IF(DATOS!D40="","",DATOS!D40) | E18: =DATOS!E40 -> 9 | F18: =DATOS!F40 -> 0.4 | G18: =DATOS!F49 -> 0.85714286 | H18: =DATOS!B93 -> 3 | I18: =DATOS!C93 -> En meta
A19: =DATOS!A41 -> Desarrollo humano | B19: =IF(DATOS!B41="","",DATOS!B41) -> 9.5 | C19: =IF(DATOS!C41="","",DATOS!C41) -> 9.6 | D19: =IF(DATOS!D41="","",DATOS!D41) | E19: =DATOS!E41 -> 9.55 | F19: =DATOS!F41 -> 0.1 | G19: =DATOS!F50 -> 1 | H19: =DATOS!B94 -> 3 | I19: =DATOS!C94 -> En meta
A20: =DATOS!A42 -> Promedio general (por evaluación) | B20: =IF(DATOS!B42="","",DATOS!B42) -> 8.28 | C20: =IF(DATOS!C42="","",DATOS!C42) -> 8.58 | D20: =IF(DATOS!D42="","",DATOS!D42) | E20: =DATOS!E42 -> 8.43 | F20: =DATOS!F42 -> 0.3 | G20: =DATOS!F51 -> 0.85 | H20: =DATOS!F71 -> 2 | I20: =DATOS!G71 -> En riesgo
A22: Objetivo 3: acciones de desarrollo profesional
A23: Cursos completados | B23: =DATOS!B62 -> 0 de 1
A24: Currículum actualizado | B24: =DATOS!B63 -> En proceso
A25: Eventos asistidos | B25: =DATOS!B64 -> 0 de 2
A27: Cómo leer el semáforo
A28: Verde: en meta | B28: Alcanza o supera la meta.
A29: Amarillo: en riesgo | B29: Debajo de la meta, pero arriba del mínimo.
A30: Rojo: bajo rendimiento | B30: Debajo del mínimo; necesito un plan de acción.
A31: Las metas y los umbrales se cambian en la hoja DATOS (sección 1).

Sheet CONCLUSIÓN
A1: CONCLUSIÓN
A3: En la primera etapa definí mi meta, mi objetivo general y tres objetivos específicos con sus actividades. En esta segunda etapa me di cuenta de que un plan escrito no basta si no tengo una forma clara de saber si lo estoy cumpliendo. Por eso agregué a cada objetivo un indicador de desempeño y un KPI. El indicador me dice qué estoy haciendo en el día a día, por ejemplo cuántos días estudié en la semana. El KPI resume si voy logrando el resultado que me propuse, como cumplir al menos el 80 % de los bloques de estudio que planifiqué.
A5: Armar el tablero en Excel también me enseñó a ordenar la información antes de graficarla. Separé los datos que registro cada semana de los cálculos y del tablero, para que todo se actualice cuando escribo un dato nuevo. Las gráficas de barras me muestran cómo cambian mis calificaciones de un parcial a otro y qué semanas cumplí mi horario; las gráficas circulares me dejan ver cuántas tareas entregué a tiempo; y las barras de progreso me recuerdan cuánto me falta para cada meta. Como dice Few (2006), un tablero sirve cuando deja ver lo importante en un solo vistazo, y eso fue lo que intenté lograr.
A7: Lo que más me sirvió fue el semáforo. Ver una materia en amarillo o en rojo me obliga a actuar antes del examen final, cuando todavía puedo pedir ayuda, repasar con preguntas y ejercicios (una de las técnicas de estudio con mejor respaldo, según Dunlosky et al., 2013) o reorganizar mi semana. También me ayuda a reconocer mis avances cuando un indicador pasa a verde, algo que en la Etapa 1 identifiqué como una necesidad. Con el tablero tomo decisiones a partir de datos y ya no solo con la sensación de que voy bien o mal.
A9: Para mi carrera profesional, esta etapa me deja herramientas que voy a seguir usando. En casi cualquier trabajo se habla de metas, indicadores y reportes, y saber diseñar un KPI, registrar datos y presentarlos con claridad es una habilidad que se puede aplicar en cualquier área. Además, dar seguimiento a mis propios objetivos fortalece la organización, la autonomía y la perseverancia, que son competencias que me propuse entrenar. Mi compromiso es actualizar el registro cada domingo, durante la revisión semanal de mi horario, y ajustar el plan cuando los datos me indiquen que algo no está funcionando.
A11: Un plan me dice a dónde quiero llegar; el tablero de control me dice si voy en camino.
A13: Valeria Ochoa – ID 5277522

Sheet TABLA DINÁMICA
A1: TABLA DINÁMICA: TAREAS POR ASIGNATURA Y ESTADO DE ENTREGA
A2: Fuente: hoja REGISTRO DE TAREAS (tabla TablaTareas). Se actualiza al abrir el archivo; si cambias datos con el archivo abierto: clic derecho sobre la tabla dinámica > Actualizar.
A4: Mes | B4: (Todas) | G4: Cómo usar los filtros
A5: Tipo de actividad | B5: (Todas) | G5: 1. Mes y Tipo de actividad (arriba de la tabla): elige uno o varios valores para filtrar todo.
G6: 2. Botones de Asignatura y Estado de entrega: muestran u ocultan asignaturas o estados.
A7: Número de tareas | B7: Estado de entrega | G7: 3. En la lista de campos puedes cambiar el cruce (por ejemplo, Promedio de Calificación por Mes).
A8: Asignatura | B8: A tiempo | C8: Con retraso | D8: No entregada | E8: Total general
A9: Matemáticas | B9: 7 | C9: 2 | D9: 1 | E9: 10
A10: Comunicación oral y escrita | B10: 8 | E10: 8
A11: Inglés | B11: 7 | C11: 1 | D11: 1 | E11: 9
A12: Tecnologías de información | B12: 6 | C12: 1 | E12: 7
A13: Desarrollo humano | B13: 6 | E13: 6
A14: Total general | B14: 34 | C14: 4 | D14: 2 | E14: 40

Sheet DATOS
A1: DATOS DEL TABLERO
A2: Los números de esta hoja son de ejemplo: cámbialos por tus datos reales y el tablero se actualiza solo. Las columnas marcadas (fórmula) se calculan solas; no las escribas.
A4: 1. Parámetros y metas
A5: Fecha de corte del reporte | B5: 46320
A6: Inicio del plan (lunes de la semana 1) | B6: 46265
A7: Duración del plan de desarrollo profesional (meses) | B7: 12
A8: Meses transcurridos (fórmula) | B8: =ROUND(MAX(0,(B5-B6)/30.44),1) -> 1.8
A9: Avance esperado del plan profesional a la fecha (fórmula) | B9: =MIN(1,B8/B7) -> 0.15
A11: Umbrales del semáforo | B11: Verde desde | C11: Amarillo desde
A12: Cumplimiento del horario (Obj. 1) | B12: 0.8 | C12: 0.6
A13: Días de estudio por semana (Obj. 1) | B13: 5 | C13: 4
A14: Tareas entregadas a tiempo (Obj. 2) | B14: 0.9 | C14: 0.75
A15: Promedio de calificaciones, escala 0 a 10 (Obj. 2) | B15: 8.5 | C15: 7
A16: Avance del plan profesional vs. avance esperado (Obj. 3) | B16: 1 | C16: 0.7
A17: Rojo (bajo rendimiento) = cualquier valor por debajo del umbral amarillo.
A19: 2. Objetivo 1: horario semanal de estudio (12 semanas)
A20: Semana | B20: Inicio de semana (fórmula) | C20: Bloques planificados | D20: Bloques realizados | E20: Días de estudio | F20: Revisión del domingo (Sí/No) | G20: % de cumplimiento (fórmula) | H20: Estado (fórmula)
A21: Semana 1 | B21: =$B$6+7*0 -> 46265 | C21: 10 | D21: 5 | E21: 3 | F21: No | G21: =IF(OR(D21="",C21=0),"",D21/C21) -> 0.5 | H21: =IF(G21="","Pendiente",IF(G21>=$B$12,"En meta",IF(G21>=$C$12,"En riesgo","Bajo rendimiento"))) -> Bajo rendimiento
A22: Semana 2 | B22: =$B$6+7*1 -> 46272 | C22: 10 | D22: 7 | E22: 4 | F22: Sí | G22: =IF(OR(D22="",C22=0),"",D22/C22) -> 0.7 | H22: =IF(G22="","Pendiente",IF(G22>=$B$12,"En meta",IF(G22>=$C$12,"En riesgo","Bajo rendimiento"))) -> En riesgo
A23: Semana 3 | B23: =$B$6+7*2 -> 46279 | C23: 10 | D23: 8 | E23: 5 | F23: Sí | G23: =IF(OR(D23="",C23=0),"",D23/C23) -> 0.8 | H23: =IF(G23="","Pendiente",IF(G23>=$B$12,"En meta",IF(G23>=$C$12,"En riesgo","Bajo rendimiento"))) -> En meta
A24: Semana 4 | B24: =$B$6+7*3 -> 46286 | C24: 10 | D24: 9 | E24: 5 | F24: Sí | G24: =IF(OR(D24="",C24=0),"",D24/C24) -> 0.9 | H24: =IF(G24="","Pendiente",IF(G24>=$B$12,"En meta",IF(G24>=$C$12,"En riesgo","Bajo rendimiento"))) -> En meta
A25: Semana 5 | B25: =$B$6+7*4 -> 46293 | C25: 10 | D25: 7 | E25: 4 | F25: No | G25: =IF(OR(D25="",C25=0),"",D25/C25) -> 0.7 | H25: =IF(G25="","Pendiente",IF(G25>=$B$12,"En meta",IF(G25>=$C$12,"En riesgo","Bajo rendimiento"))) -> En riesgo
A26: Semana 6 | B26: =$B$6+7*5 -> 46300 | C26: 10 | D26: 9 | E26: 5 | F26: Sí | G26: =IF(OR(D26="",C26=0),"",D26/C26) -> 0.9 | H26: =IF(G26="","Pendiente",IF(G26>=$B$12,"En meta",IF(G26>=$C$12,"En riesgo","Bajo rendimiento"))) -> En meta
A27: Semana 7 | B27: =$B$6+7*6 -> 46307 | C27: 10 | D27: 10 | E27: 5 | F27: Sí | G27: =IF(OR(D27="",C27=0),"",D27/C27) -> 1 | H27: =IF(G27="","Pendiente",IF(G27>=$B$12,"En meta",IF(G27>=$C$12,"En riesgo","Bajo rendimiento"))) -> En meta
A28: Semana 8 | B28: =$B$6+7*7 -> 46314 | C28: 10 | D28: 10 | E28: 5 | F28: Sí | G28: =IF(OR(D28="",C28=0),"",D28/C28) -> 1 | H28: =IF(G28="","Pendiente",IF(G28>=$B$12,"En meta",IF(G28>=$C$12,"En riesgo","Bajo rendimiento"))) -> En meta
A29: Semana 9 | B29: =$B$6+7*8 -> 46321 | C29: 10 | G29: =IF(OR(D29="",C29=0),"",D29/C29) | H29: =IF(G29="","Pendiente",IF(G29>=$B$12,"En meta",IF(G29>=$C$12,"En riesgo","Bajo rendimiento"))) -> Pendiente
A30: Semana 10 | B30: =$B$6+7*9 -> 46328 | C30: 10 | G30: =IF(OR(D30="",C30=0),"",D30/C30) | H30: =IF(G30="","Pendiente",IF(G30>=$B$12,"En meta",IF(G30>=$C$12,"En riesgo","Bajo rendimiento"))) -> Pendiente
A31: Semana 11 | B31: =$B$6+7*10 -> 46335 | C31: 10 | G31: =IF(OR(D31="",C31=0),"",D31/C31) | H31: =IF(G31="","Pendiente",IF(G31>=$B$12,"En meta",IF(G31>=$C$12,"En riesgo","Bajo rendimiento"))) -> Pendiente
A32: Semana 12 | B32: =$B$6+7*11 -> 46342 | C32: 10 | G32: =IF(OR(D32="",C32=0),"",D32/C32) | H32: =IF(G32="","Pendiente",IF(G32>=$B$12,"En meta",IF(G32>=$C$12,"En riesgo","Bajo rendimiento"))) -> Pendiente
A33: Total de las semanas registradas | B33: =COUNT(D21:D32)&" de 12" -> 8 de 12 | C33: =SUMPRODUCT((D21:D32<>"")*C21:C32) -> 80 | D33: =SUM(D21:D32) -> 65 | E33: =IFERROR(AVERAGE(E21:E32),0) -> 4.5 | F33: =COUNTIF(F21:F32,"Sí") -> 6 | G33: =IF(C33=0,0,D33/C33) -> 0.8125 | H33: =IF(G33>=$B$12,"En meta",IF(G33>=$C$12,"En riesgo","Bajo rendimiento")) -> En meta
A35: 3. Objetivo 2: calificaciones por asignatura (escala 0 a 10)
A36: Asignatura | B36: Parcial 1 | C36: Parcial 2 | D36: Parcial 3 / Final | E36: Promedio (fórmula) | F36: Variación (fórmula) | G36: Estado (fórmula)
A37: Matemáticas | B37: 6.2 | C37: 7 | E37: =IF(COUNT(B37:D37)=0,"",AVERAGE(B37:D37)) -> 6.6 | F37: =IFERROR(IF(COUNT(B37:D37)<2,"",IF(D37<>"",D37,C37)-B37),"") -> 0.8 | G37: =IF(E37="","Pendiente",IF(E37>=$B$15,"En meta",IF(E37>=$C$15,"En riesgo","Bajo rendimiento"))) -> Bajo rendimiento
A38: Comunicación oral y escrita | B38: 8.9 | C38: 9.3 | E38: =IF(COUNT(B38:D38)=0,"",AVERAGE(B38:D38)) -> 9.1 | F38: =IFERROR(IF(COUNT(B38:D38)<2,"",IF(D38<>"",D38,C38)-B38),"") -> 0.4 | G38: =IF(E38="","Pendiente",IF(E38>=$B$15,"En meta",IF(E38>=$C$15,"En riesgo","Bajo rendimiento"))) -> En meta
A39: Inglés | B39: 8 | C39: 7.8 | E39: =IF(COUNT(B39:D39)=0,"",AVERAGE(B39:D39)) -> 7.9 | F39: =IFERROR(IF(COUNT(B39:D39)<2,"",IF(D39<>"",D39,C39)-B39),"") -> -0.2 | G39: =IF(E39="","Pendiente",IF(E39>=$B$15,"En meta",IF(E39>=$C$15,"En riesgo","Bajo rendimiento"))) -> En riesgo
A40: Tecnologías de información | B40: 8.8 | C40: 9.2 | E40: =IF(COUNT(B40:D40)=0,"",AVERAGE(B40:D40)) -> 9 | F40: =IFERROR(IF(COUNT(B40:D40)<2,"",IF(D40<>"",D40,C40)-B40),"") -> 0.4 | G40: =IF(E40="","Pendiente",IF(E40>=$B$15,"En meta",IF(E40>=$C$15,"En riesgo","Bajo rendimiento"))) -> En meta
A41: Desarrollo humano | B41: 9.5 | C41: 9.6 | E41: =IF(COUNT(B41:D41)=0,"",AVERAGE(B41:D41)) -> 9.55 | F41: =IFERROR(IF(COUNT(B41:D41)<2,"",IF(D41<>"",D41,C41)-B41),"") -> 0.1 | G41: =IF(E41="","Pendiente",IF(E41>=$B$15,"En meta",IF(E41>=$C$15,"En riesgo","Bajo rendimiento"))) -> En meta
A42: Promedio general (por evaluación) | B42: =IFERROR(AVERAGE(B37:B41),"") -> 8.28 | C42: =IFERROR(AVERAGE(C37:C41),"") -> 8.58 | D42: =IFERROR(AVERAGE(D37:D41),"") | E42: =IFERROR(AVERAGE(E37:E41),0) -> 8.43 | F42: =IFERROR(IF(COUNT(B42:D42)<2,"",IF(D42<>"",D42,C42)-B42),"") -> 0.3 | G42: =IF(E42>=$B$15,"En meta",IF(E42>=$C$15,"En riesgo","Bajo rendimiento")) -> En riesgo
A44: 4. Objetivo 2: entrega de tareas (se calcula sola desde la hoja REGISTRO DE TAREAS)
A45: Asignatura | B45: Tareas asignadas (fórmula) | C45: Entregadas a tiempo (fórmula) | D45: Entregadas con retraso (fórmula) | E45: No entregadas (fórmula) | F45: % a tiempo (fórmula) | G45: Estado (fórmula)
...

Sheet REGISTRO DE TAREAS
A1: REGISTRO DE TAREAS (fuente de la tabla dinámica)
A2: Una fila por tarea. Las tareas nuevas se escriben en la primera fila vacía debajo de la tabla (la tabla crece sola). La columna Mes se calcula sola. Los datos son de ejemplo: cámbialos por tus tareas reales.
A4: N.º | B4: Fecha de entrega | C4: Mes | D4: Asignatura | E4: Tipo de actividad | F4: Estado de entrega | G4: Calificación
A5: 1 | B5: 46267 | C5: =IF(B5="","",CHOOSE(MONTH(B5),"Enero","Febrero","Marzo","Abril","Mayo","Junio","Julio","Agosto","Septiembre","Octubre","Noviembre","Diciembre")) -> Septiembre | D5: Matemáticas | E5: Tarea | F5: A tiempo | G5: 7.3
A6: 2 | B6: 46268 | C6: =IF(B6="","",CHOOSE(MONTH(B6),"Enero","Febrero","Marzo","Abril","Mayo","Junio","Julio","Agosto","Septiembre","Octubre","Noviembre","Diciembre")) -> Septiembre | D6: Comunicación oral y escrita | E6: Tarea | F6: A tiempo | G6: 8.9
A7: 3 | B7: 46269 | C7: =IF(B7="","",CHOOSE(MONTH(B7),"Enero","Febrero","Marzo","Abril","Mayo","Junio","Julio","Agosto","Septiembre","Octubre","Noviembre","Diciembre")) -> Septiembre | D7: Inglés | E7: Tarea | F7: A tiempo | G7: 7.9
A8: 4 | B8: 46270 | C8: =IF(B8="","",CHOOSE(MONTH(B8),"Enero","Febrero","Marzo","Abril","Mayo","Junio","Julio","Agosto","Septiembre","Octubre","Noviembre","Diciembre")) -> Septiembre | D8: Tecnologías de información | E8: Tarea | F8: A tiempo | G8: 8.7
A9: 5 | B9: 46271 | C9: =IF(B9="","",CHOOSE(MONTH(B9),"Enero","Febrero","Marzo","Abril","Mayo","Junio","Julio","Agosto","Septiembre","Octubre","Noviembre","Diciembre")) -> Septiembre | D9: Desarrollo humano | E9: Tarea | F9: A tiempo | G9: 9.3
A10: 6 | B10: 46271 | C10: =IF(B10="","",CHOOSE(MONTH(B10),"Enero","Febrero","Marzo","Abril","Mayo","Junio","Julio","Agosto","Septiembre","Octubre","Noviembre","Diciembre")) -> Septiembre | D10: Matemáticas | E10: Ejercicios de repaso | F10: Con retraso | G10: 6.6
A11: 7 | B11: 46274 | C11: =IF(B11="","",CHOOSE(MONTH(B11),"Enero","Febrero","Marzo","Abril","Mayo","Junio","Julio","Agosto","Septiembre","Octubre","Noviembre","Diciembre")) -> Septiembre | D11: Comunicación oral y escrita | E11: Ejercicios de repaso | F11: A tiempo | G11: 9.2
A12: 8 | B12: 46274 | C12: =IF(B12="","",CHOOSE(MONTH(B12),"Enero","Febrero","Marzo","Abril","Mayo","Junio","Julio","Agosto","Septiembre","Octubre","Noviembre","Diciembre")) -> Septiembre | D12: Inglés | E12: Ejercicios de repaso | F12: Con retraso | G12: 7.2
A13: 9 | B13: 46275 | C13: =IF(B13="","",CHOOSE(MONTH(B13),"Enero","Febrero","Marzo","Abril","Mayo","Junio","Julio","Agosto","Septiembre","Octubre","Noviembre","Diciembre")) -> Septiembre | D13: Matemáticas | E13: Tarea | F13: No entregada
A14: 10 | B14: 46276 | C14: =IF(B14="","",CHOOSE(MONTH(B14),"Enero","Febrero","Marzo","Abril","Mayo","Junio","Julio","Agosto","Septiembre","Octubre","Noviembre","Diciembre")) -> Septiembre | D14: Tecnologías de información | E14: Ejercicios de repaso | F14: Con retraso | G14: 8
A15: 11 | B15: 46279 | C15: =IF(B15="","",CHOOSE(MONTH(B15),"Enero","Febrero","Marzo","Abril","Mayo","Junio","Julio","Agosto","Septiembre","Octubre","Noviembre","Diciembre")) -> Septiembre | D15: Desarrollo humano | E15: Ejercicios de repaso | F15: A tiempo | G15: 9.6
A16: 12 | B16: 46279 | C16: =IF(B16="","",CHOOSE(MONTH(B16),"Enero","Febrero","Marzo","Abril","Mayo","Junio","Julio","Agosto","Septiembre","Octubre","Noviembre","Diciembre")) -> Septiembre | D16: Inglés | E16: Tarea | F16: No entregada
A17: 13 | B17: 46279 | C17: =IF(B17="","",CHOOSE(MONTH(B17),"Enero","Febrero","Marzo","Abril","Mayo","Junio","Julio","Agosto","Septiembre","Octubre","Noviembre","Diciembre")) -> Septiembre | D17: Matemáticas | E17: Reporte de lectura | F17: Con retraso | G17: 6.3
A18: 14 | B18: 46280 | C18: =IF(B18="","",CHOOSE(MONTH(B18),"Enero","Febrero","Marzo","Abril","Mayo","Junio","Julio","Agosto","Septiembre","Octubre","Noviembre","Diciembre")) -> Septiembre | D18: Comunicación oral y escrita | E18: Tarea | F18: A tiempo | G18: 9.5
A19: 15 | B19: 46282 | C19: =IF(B19="","",CHOOSE(MONTH(B19),"Enero","Febrero","Marzo","Abril","Mayo","Junio","Julio","Agosto","Septiembre","Octubre","Noviembre","Diciembre")) -> Septiembre | D19: Tecnologías de información | E19: Tarea | F19: A tiempo | G19: 9.3
A20: 16 | B20: 46283 | C20: =IF(B20="","",CHOOSE(MONTH(B20),"Enero","Febrero","Marzo","Abril","Mayo","Junio","Julio","Agosto","Septiembre","Octubre","Noviembre","Diciembre")) -> Septiembre | D20: Matemáticas | E20: Proyecto | F20: A tiempo | G20: 7.6
A21: 17 | B21: 46284 | C21: =IF(B21="","",CHOOSE(MONTH(B21),"Enero","Febrero","Marzo","Abril","Mayo","Junio","Julio","Agosto","Septiembre","Octubre","Noviembre","Diciembre")) -> Septiembre | D21: Inglés | E21: Reporte de lectura | F21: A tiempo | G21: 7.9
A22: 18 | B22: 46286 | C22: =IF(B22="","",CHOOSE(MONTH(B22),"Enero","Febrero","Marzo","Abril","Mayo","Junio","Julio","Agosto","Septiembre","Octubre","Noviembre","Diciembre")) -> Septiembre | D22: Comunicación oral y escrita | E22: Reporte de lectura | F22: A tiempo | G22: 8.9
A23: 19 | B23: 46287 | C23: =IF(B23="","",CHOOSE(MONTH(B23),"Enero","Febrero","Marzo","Abril","Mayo","Junio","Julio","Agosto","Septiembre","Octubre","Noviembre","Diciembre")) -> Septiembre | D23: Desarrollo humano | E23: Tarea | F23: A tiempo | G23: 9.9
A24: 20 | B24: 46287 | C24: =IF(B24="","",CHOOSE(MONTH(B24),"Enero","Febrero","Marzo","Abril","Mayo","Junio","Julio","Agosto","Septiembre","Octubre","Noviembre","Diciembre")) -> Septiembre | D24: Matemáticas | E24: Tarea | F24: A tiempo | G24: 7.9
A25: 21 | B25: 46288 | C25: =IF(B25="","",CHOOSE(MONTH(B25),"Enero","Febrero","Marzo","Abril","Mayo","Junio","Julio","Agosto","Septiembre","Octubre","Noviembre","Diciembre")) -> Septiembre | D25: Tecnologías de información | E25: Reporte de lectura | F25: A tiempo | G25: 8.7
A26: 22 | B26: 46289 | C26: =IF(B26="","",CHOOSE(MONTH(B26),"Enero","Febrero","Marzo","Abril","Mayo","Junio","Julio","Agosto","Septiembre","Octubre","Noviembre","Diciembre")) -> Septiembre | D26: Inglés | E26: Proyecto | F26: A tiempo | G26: 8.2
A27: 23 | B27: 46291 | C27: =IF(B27="","",CHOOSE(MONTH(B27),"Enero","Febrero","Marzo","Abril","Mayo","Junio","Julio","Agosto","Septiembre","Octubre","Noviembre","Diciembre")) -> Septiembre | D27: Matemáticas | E27: Ejercicios de repaso | F27: A tiempo | G27: 7.3
A28: 24 | B28: 46292 | C28: =IF(B28="","",CHOOSE(MONTH(B28),"Enero","Febrero","Marzo","Abril","Mayo","Junio","Julio","Agosto","Septiembre","Octubre","Noviembre","Diciembre")) -> Septiembre | D28: Comunicación oral y escrita | E28: Proyecto | F28: A tiempo | G28: 9.2
... A44: 40 | B44: 46311 | C44: =IF(B44="","",CHOOSE(MONTH(B44),"Enero","Febrero","Marzo","Abril","Mayo","Junio","Julio","Agosto","Septiembre","Octubre","Noviembre","Diciembre")) -> Octubre | D44: Desarrollo humano | E44: Tarea | F44: A tiempo | G44: 9.9

Sheet REFERENCIAS
A1: REFERENCIAS
A3: Dunlosky, J., Rawson, K. A., Marsh, E. J., Nathan, M. J., & Willingham, D. T. (2013). Improving students’ learning with effective learning techniques: Promising directions from cognitive and educational psychology. Psychological Science in the Public Interest, 14(1), 4–58. https://doi.org/10.1177/1529100612453266
A4: Few, S. (2006). Information dashboard design: The effective visual communication of data. O’Reilly Media.
A5: Parmenter, D. (2015). Key performance indicators: Developing, implementing, and using winning KPIs (3rd ed.). John Wiley & Sons.
A7: Videos de apoyo del curso (YouTube)
A8: https://www.youtube.com/watch?v=830NHbvbo5g
A9: https://www.youtube.com/watch?v=Oanr41Tz28U
A10: https://www.youtube.com/watch?v=Pfi1kE2tYBs
A11: https://www.youtube.com/watch?v=D3kV5dMn5fk
A12: https://www.youtube.com/watch?v=1SEOOoMEm78
